<?xml version="1.0"?>
<robot name="visual">
   
<material name="blue">
    <color rgba="0.00784313725490196 0.8470588235294118 0.9137254901960784 1.0" />
  </material>
  <material name="amethyst" >
    <color rgba="0.6078431372549019 0.37254901960784315 0.7529411764705882 1.0" />
  </material>
  <material name="black">
    <color rgba="0 0 0 1"/>
  </material>
  <material name="white">
    <color rgba="1 1 1 1"/>
  </material>

  <link name="base_link">
    <visual>
      <geometry>
        <cylinder length="0.6" radius="0.2"/>
      </geometry>
      <material name="blue"/>
    </visual>
  </link>

  <link name="right_leg">
    <visual>
      <geometry>
        <box size="0.6 0.1 0.2"/>
      </geometry>
      <origin rpy="0 1.57075 0" xyz="0 0 -0.3"/>
      <material name="white"/>
    </visual>
  </link>

  <joint name="base_to_right_leg" type="fixed">
    <parent link="base_link"/>
    <child link="right_leg"/>
    <origin xyz="0 -0.22 0.25"/>
  </joint>

 <link name="left_leg">
    <visual>
      <geometry>
        <box size="0.6 0.1 0.2"/>
      </geometry>
      <origin rpy="0 1.57075 0" xyz="0 0 -0.3"/>
      <material name="white"/>
    </visual>
  </link>

  <joint name="base_to_left_leg" type="fixed">
    <parent link="base_link"/>
    <child link="left_leg"/>
    <origin xyz="0 0.22 0.25"/>
  </joint>

  <link name="right_base">
    <visual>
      <geometry>
        <box size="0.4 0.1 0.1"/>
      </geometry>
      <material name="white"/>
    </visual>
  </link>

  <joint name="right_base_joint" type="fixed">
    <parent link="right_leg"/>
    <child link="right_base"/>
    <origin xyz="0 0 -0.6"/>
  </joint>

   <link name="left_base">
    <visual>
      <geometry>
        <box size="0.4 0.1 0.1"/>
      </geometry>
      <material name="white"/>
    </visual>
  </link>

  <joint name="left_base_joint" type="fixed">
    <parent link="left_leg"/>
    <child link="left_base"/>
    <origin xyz="0 0 -0.6"/>
  </joint>


  <link name="right_front_wheel">
    <visual>
      <origin rpy="1.57075 0 0" xyz="0 0 0"/>
      <geometry>
        <cylinder length="0.1" radius="0.035"/>
      </geometry>
      <material name="black"/>
      <origin rpy="0 0 0" xyz="0 0 0"/>
    </visual>
  </link>
  
   <joint name="right_front_wheel_joint" type="continuous">
    <axis rpy="0 0 0" xyz="0 1 0"/>
    <parent link="right_base"/>
    <child link="right_front_wheel"/>
    <origin rpy="0 0 0" xyz="0.133333333333 0 -0.085"/>
  </joint>


  <link name="right_back_wheel">
    <visual>
      <origin rpy="1.57075 0 0" xyz="0 0 0"/>
      <geometry>
        <cylinder length="0.1" radius="0.035"/>
      </geometry>
      <material name="black"/>
    </visual>
  </link>
  
  <joint name="right_back_wheel_joint" type="continuous">
    <axis rpy="0 0 0" xyz="0 1 0"/>
    <parent link="right_base"/>
    <child link="right_back_wheel"/>
    <origin rpy="0 0 0" xyz="-0.133333333333 0 -0.085"/>
  </joint>

  <link name="left_front_wheel">
    <visual>
      <origin rpy="1.57075 0 0" xyz="0 0 0"/>
      <geometry>
        <cylinder length="0.1" radius="0.035"/>
      </geometry>
      <material name="black"/>
    </visual>
  </link>
  
  <joint name="left_front_wheel_joint" type="prismatic">
    <axis rpy="0 0 0" xyz="0 1 0"/>
    <parent link="left_base"/>
    <child link="left_front_wheel"/>
    <origin rpy="0 0 0" xyz="0.133333333333 0 -0.085"/>
    <limit effort="1000.0" lower="-0.1" upper="0.15" velocity="0.5"/>
  </joint>


  <link name="left_back_wheel">
    <visual>
      <origin rpy="1.57075 0 0" xyz="0 0 0"/>
      <geometry>
        <cylinder length="0.1" radius="0.035"/>
      </geometry>
      <material name="black"/>
    </visual>
  </link>
  
   <joint name="left_back_wheel_joint" type="prismatic">
    <axis rpy="0 0 0" xyz="0 1 0"/>
    <parent link="left_base"/>
    <child link="left_back_wheel"/>
    <origin rpy="0 0 0" xyz="-0.133333333333 0 -0.085"/>
    <limit effort="1000.0" lower="-0.1" upper="0.15" velocity="0.5"/>
  </joint>
  
  <link name="extender">
    <visual>
      <origin xyz="0 0 0.3" rpy="0 0 0" />
      <geometry>
        <cylinder length="0.4" radius="0.05"/>
      </geometry>
      <material name="amethyst"/>
    </visual>
  </link>

 <joint name="base_to_extender" type="prismatic">
    <parent link="base_link"/>
    <child link="extender"/>
    <axis xyz="0 0 1"/>
    <limit effort="1000.0" lower="-0.1" upper="0.15" velocity="0.5"/>
  </joint>

 <link name="rotator">
    <visual>
      <origin xyz="0.15 0 0.5" rpy="0 1.3 0" />
      <geometry>
        <cylinder length="0.4" radius="0.05"/>
      </geometry>
      <material name="amethyst"/>
    </visual>
  </link>
  
  <joint name="extender_to_rotator" type="continuous">
    <parent link="extender"/>
    <child link="rotator"/>
    <axis xyz="0 0 1"/>
  </joint>
 

  <link name="end_effector">
    <visual>
      <origin xyz="0.35 0 0.6" rpy="0 0 0" />
      <geometry>
        <cylinder length="0.2" radius="0.05"/>
      </geometry>
      <material name="amethyst"/>
    </visual>
  </link>
  
   <joint name="rotator_to_endeff" type="fixed">
    <parent link="rotator"/>
    <child link="end_effector"/>
  </joint>


  <link name="tray">
    <visual>
     <origin xyz="0.35 0 0.7" rpy="0 0 0" />
      <geometry>
        <box size="0.3 0.6 0.05"/>
      </geometry>
      <material name="white"/>
    </visual>
  </link>

<joint name="end_to_tray" type="fixed">
    <parent link="end_effector"/>
    <child link="tray"/>
  </joint>


</robot>
